from django.conf import settings


def pytest_configure():
    settings.configure(
        DEBUG_PROPAGATE_EXCEPTIONS=True,
        DATABASES={
            'default': {
                'ENGINE': 'django.db.backends.sqlite3',
                'NAME': ':memory:'
            }
        },
        SECRET_KEY='not very secret in tests',
        USE_I18N=True,
        USE_L10N=True,
        ROOT_URLCONF='tests.urls',
        TEMPLATES=[
            {
                'BACKEND': 'django.template.backends.django.DjangoTemplates',
                'APP_DIRS': True,
            },
        ],
        MIDDLEWARE_CLASSES=(
            'django.middleware.common.CommonMiddleware',
            'django.contrib.sessions.middleware.SessionMiddleware',
            'django.contrib.auth.middleware.AuthenticationMiddleware',
            'django.contrib.messages.middleware.MessageMiddleware',
        ),
        INSTALLED_APPS=(
            'django.contrib.auth',
            'django.contrib.contenttypes',
            'django.contrib.sessions',
            'django.contrib.sites',
            'django.contrib.staticfiles',
            'patchy',
            'tests',
        ),
    )

    try:
        import django
        django.setup()
    except AttributeError:
        pass
